Workbook

Sheet Home
A1: INDUSTRY/SECTOR NAME | B1: COMPANY NAME (TOP 5) | C1: COMPANY NAME (BOTTOM 5)
A2: FMCG | B2: HINDUSTAN UNILEVER LTD | C2: GODFREY PHILLIPS INDIA LTD
B3: ITC LTD | C3: KRBL LTD
B4: NESTLE INDIA LTD | C4: BAJAJ HINDUSTHAN SUGAR LTD
B5: VARUN BEVERAGES LTD | C5: DEVYANI INTERNATIONAL LTD
B6: BRITANNIA INDUSTRIES LTD | C6: RADICO KHAITAN LTD
A7: AUTOMOTIVE | B7: TATA MOTORS | C7: SKF INDIA
B8: MAHINDRA AND MAHINDRA | C8: MINDA CORPORATION
B9: MARUTI SUZUKI INDIA | C9: TENNECO CLEAN AIR INDIA LTD
B10: SAMVARDHANA MOTHERSON INTERNATIONAL | C10: ASAHI INDIA GLASS
B11: HYUNDAI MOTOR INDIA | C11: WHEELS INDIA
A12: ENERGY | B12: RELIANCE INDUSTRIES LTD | C12: PETRONET LNG
B13: INDIAN OIL CORPORATION | C13: PREMIER ENERGY
B14: BHARAT PETROLEUM CORPORATION | C14: JAIPRAKASH POWER VENTURES
B15: ONGC | C15: TRANSRAIL LIGHTING
B16: GAIL | C16: ADANI TOTAL GAS
A17: METALS | B17: HINDALCO INDUSTRIES LTD | C17: GODAWARI POWER AND ISPAT LTD
B18: TATA STEEL LTD | C18: MAHARASHTRA SEAMLESS LTD
B19: JSW STEEL | C19: RATNAMANI METALS AND TUBES
B20: VEDANTA LTD | C20: MUKAND LTD
B21: STEEL AUTHORITY OF INDIA | C21: SARDA ENERGY AND MINERALS
A22: PHARMA | B22: SUN PHARMACEUTICALS INDUSTRIES | C22: ABBOTT INDIA LTD
B23: DR REDDY'S LABORATORIES | C23: GLAND PHARMA LTD
B24: AUROBINDO PHARMA | C24: LAURUS LABS LTD
B25: CIPLA | C25: NATCO PHARMA
B26: ZYDUS LIFESCIENCES | C26: AJANTA PHARMA

Sheet Working Capital Analysis
A1: INDUSTRY | B1: TYPE | C1: FY25 | D1: FY24 | E1: FY23 | F1: FY22 | G1: FY21 | H1: FY20
A2: FMCG | B2: AVERAGE WORKING CAPITAL (ALL 10) | C2: =FMCG!C203 -> 4191.034 | D2: =FMCG!D203 -> 4190.799 | E2: =FMCG!E203 -> 3349.898 | F2: =FMCG!F203 -> 3093.634 | G2: =FMCG!G203 -> 3626.5778 | H2: =FMCG!H203 -> 4340.1678
B3: AVERAGE CCC (ALL 10) | C3: =FMCG!C204 -> 71.469085 | D3: =FMCG!D204 -> 64.868809 | E3: =FMCG!E204 -> 60.684045 | F3: =FMCG!F204 -> 62.081887 | G3: =FMCG!G204 -> 74.422336
B4: TOP 5 AVERAGE WORKING CAPITAL | C4: =FMCG!C206 -> 7647.898 | D4: =FMCG!D206 -> 7893.116 | E4: =FMCG!E206 -> 6279.772 | F4: =FMCG!F206 -> 5194.222 | G4: =FMCG!G206 -> 5576.634
B5: TOP 5 AVERAGE CCC | C5: =FMCG!C207 -> 27.775558 | D5: =FMCG!D207 -> 23.885472 | E5: =FMCG!E207 -> 24.218533 | F5: =FMCG!F207 -> 21.218624 | G5: =FMCG!G207 -> 19.131972
B6: BOTTOM 5 AVERAGE WORKING CAPITAL | C6: =FMCG!C209 -> 734.17 | D6: =FMCG!D209 -> 488.482 | E6: =FMCG!E209 -> 420.024 | F6: =FMCG!F209 -> 993.046 | G6: =FMCG!G209 -> 1189.0075
B7: BOTTOM 5 AVERAGE CCC | C7: =FMCG!C210 -> 115.16261 | D7: =FMCG!D210 -> 105.85215 | E7: =FMCG!E210 -> 97.149556 | F7: =FMCG!F210 -> 102.94515 | G7: 110
A9: AUTOMOTIVE | B9: AVERAGE WORKING CAPITAL (ALL 10) | C9: =Automotive!C203 -> 3609.114 | D9: =Automotive!D203 -> 1831.589 | E9: =Automotive!E203 -> 2323.694 | F9: =Automotive!F203 -> 2794.541 | G9: =Automotive!G203 -> 2491.8533 | H9: =Automotive!H203 -> -586.18889
B10: AVERAGE CCC (ALL 10) | C10: =Automotive!C204 -> 1.2629324 | D10: =Automotive!D204 -> 5.7836735 | E10: =Automotive!E204 -> 9.7131422 | F10: =Automotive!F204 -> 5.3854899 | G10: =Automotive!G204 -> 8.2609065
B11: TOP 5 AVERAGE WORKING CAPITAL | C11: =Automotive!C206 -> 6970.096 | D11: =Automotive!D206 -> 3171.158 | E11: =Automotive!E206 -> 4275.144 | F11: =Automotive!F206 -> 5228.58 | G11: =Automotive!G206 -> 4242.324
B12: TOP 5 AVERAGE CCC | C12: =Automotive!C207 -> -26.476812 | D12: =Automotive!D207 -> -21.090319 | E12: =Automotive!E207 -> -17.166165 | F12: =Automotive!F207 -> -24.519473 | G12: =Automotive!G207 -> -27.361934
B13: BOTTOM 5 AVERAGE WORKING CAPITAL | C13: =FMCG!C209 -> 734.17 | D13: =FMCG!D209 -> 488.482 | E13: =FMCG!E209 -> 420.024 | F13: =FMCG!F209 -> 993.046 | G13: =FMCG!G209 -> 1189.0075
B14: BOTTOM 5 AVERAGE CCC | C14: =FMCG!C210 -> 115.16261 | D14: =FMCG!D210 -> 105.85215 | E14: =FMCG!E210 -> 97.149556 | F14: =FMCG!F210 -> 102.94515 | G14: =FMCG!G210 -> 143.53529
A16: ENERGY | B16: AVERAGE WORKING CAPITAL (ALL 10) | C16: ='Energy '!C203 -> -9489.991 | D16: ='Energy '!D203 -> -5930.83 | E16: ='Energy '!E203 -> -4868.983 | F16: ='Energy '!F203 -> -5931.63 | G16: ='Energy '!G203 -> -6778.857
B17: AVERAGE CCC (ALL 10) | C17: ='Energy '!C204 -> 18.009928 | D17: ='Energy '!D204 -> 15.532443 | E17: ='Energy '!E204 -> 11.499665 | F17: ='Energy '!F204 -> 10.432729 | G17: ='Energy '!G204 -> 16.598564
B18: TOP 5 AVERAGE WORKING CAPITAL | C18: ='Energy '!C206 -> -22325.264 | D18: ='Energy '!D206 -> -13967.818 | E18: ='Energy '!E206 -> -11453.12 | F18: ='Energy '!F206 -> -13019.536 | G18: ='Energy '!G206 -> -14749.556
B19: TOP 5 AVERAGE CCC | C19: ='Energy '!C207 -> 17.054511 | D19: ='Energy '!D207 -> 15.087785 | E19: ='Energy '!E207 -> 8.7607728 | F19: ='Energy '!F207 -> 10.521014 | G19: ='Energy '!G207 -> 17.706232
B20: BOTTOM 5 AVERAGE WORKING CAPITAL | C20: ='Energy '!C209 -> 3345.282 | D20: ='Energy '!D209 -> 2106.158 | E20: ='Energy '!E209 -> 1715.154 | F20: ='Energy '!F209 -> 1156.276 | G20: ='Energy '!G209 -> 1191.842
B21: BOTTOM 5 AVERAGE CCC | C21: ='Energy '!C210 -> 18.965344 | D21: ='Energy '!D210 -> 15.977102 | E21: ='Energy '!E210 -> 14.238557 | F21: ='Energy '!F210 -> 10.344444 | G21: ='Energy '!G210 -> 15.490897
A23: METALS | B23: AVERAGE WORKING CAPITAL (ALL 10) | C23: =Metals!C203 -> 1753.674 | D23: =Metals!D203 -> -2333.545 | E23: =Metals!E203 -> -892.826 | F23: =Metals!F203 -> 3454.786 | G23: =Metals!G203 -> -652.413 | H23: =Metals!H203 -> 1301.473
B24: AVERAGE CCC (ALL 10) | C24: =Metals!C204 -> 107.59372 | D24: =Metals!D204 -> 93.312068 | E24: =Metals!E204 -> 77.459847 | F24: =Metals!F204 -> 77.375496 | G24: =Metals!G204 -> 105.97579
B25: TOP 5 AVERAGE WORKING CAPITAL | C25: =Metals!C206 -> 1466.252 | D25: =Metals!D206 -> -6766.536 | E25: =Metals!E206 -> -3562.392 | F25: =Metals!F206 -> 5605.316 | G25: =Metals!G206 -> -2395.272
B26: TOP 5 AVERAGE CCC | C26: =Metals!C207 -> 80.629786 | D26: =Metals!D207 -> 64.089892 | E26: =Metals!E207 -> 42.401071 | F26: =Metals!F207 -> 43.935988 | G26: =Metals!G207 -> 78.45814
B27: BOTTOM 5 AVERAGE WORKING CAPITAL | C27: =Metals!C209 -> 2041.096 | D27: =Metals!D209 -> 2099.446 | E27: =Metals!E209 -> 1776.74 | F27: =Metals!F209 -> 1304.256 | G27: =Metals!G209 -> 1090.446
B28: BOTTOM 5 AVERAGE CCC | C28: =Metals!C210 -> 134.55765 | D28: =Metals!D210 -> 122.53424 | E28: =Metals!E210 -> 112.51862 | F28: =Metals!F210 -> 110.815 | G28: =Metals!G210 -> 133.49344
A30: PHARMA | B30: AVERAGE WORKING CAPITAL (ALL 10) | C30: =Pharma!C203 -> 10024.572 | D30: =Pharma!D203 -> 8582.798 | E30: =Pharma!E203 -> 7156.472 | F30: =Pharma!F203 -> 6202.134 | G30: =Pharma!G203 -> 5028.111 | H30: =Pharma!H203 -> 4171.386
B31: AVERAGE CCC (ALL 10) | C31: =Pharma!C204 -> 215.58123 | D31: =Pharma!D204 -> 211.61664 | E31: =Pharma!E204 -> 222.13207 | F31: =Pharma!F204 -> 228.8944 | G31: =Pharma!G204 -> 218.80489
B32: TOP 5 AVERAGE WORKING CAPITAL | C32: =Pharma!C206 -> 16940.748 | D32: =Pharma!D206 -> 14813.904 | E32: =Pharma!E206 -> 11706.522 | F32: =Pharma!F206 -> 10006.794 | G32: =Pharma!G206 -> 7874.794
B33: TOP 5 AVERAGE CCC | C33: =Pharma!C207 -> 205.33546 | D33: =Pharma!D207 -> 201.87178 | E33: =Pharma!E207 -> 207.83109 | F33: =Pharma!F207 -> 216.59005 | G33: =Pharma!G207 -> 228.19477
B34: BOTTOM 5 AVERAGE WORKING CAPITAL | C34: =Pharma!C209 -> 3108.396 | D34: =Pharma!D209 -> 2351.692 | E34: =Pharma!E209 -> 2606.422 | F34: =Pharma!F209 -> 2397.474 | G34: =Pharma!G209 -> 2181.428
B35: BOTTOM 5 AVERAGE CCC | C35: =Pharma!C210 -> 225.827 | D35: =Pharma!D210 -> 221.36151 | E35: =Pharma!E210 -> 236.43306 | F35: =Pharma!F210 -> 241.19874 | G35: =Pharma!G210 -> 209.41502

Sheet FMCG
A1: HUL
A2: Figures (In Crores) | C2: FY25 | D2: FY24 | E2: FY23 | F2: FY22 | G2: FY21 | H2: FY20
A3: Net Revenue from Operations | C3: 62288 | D3: 60966 | E3: 59549 | F3: 51548 | G3: 46321 | H3: 39238
A4: COGS | C4: 30578 | D4: 29760 | E4: 31716 | F4: 25735 | G4: 22148 | H4: 18259
A5: Current Assets | C5: 22051 | D5: 21324 | E5: 16998 | F5: 15522 | G5: 14217 | H5: 12321
A6: Inventory | C6: 4415 | D6: 4022 | E6: 4251 | F6: 4096 | G6: 3579 | H6: 2767
A7: Trade Receivables | C7: 3819 | D7: 2997 | E7: 3079 | F7: 2236 | G7: 1758 | H7: 1149
A8: Current Liability | C8: 16537 | D8: 12876 | E8: 12028 | F8: 11280 | G8: 11103 | H8: 9317
A9: Trade Payables | C9: 11315 | D9: 10486 | E9: 9574 | F9: 9068 | G9: 8802 | H9: 7535
A11: ANALYSIS PART
A12: WORKING CAPITAL | B12: CURRENT ASSETS - CURRENT LIABILITY | C12: =C5-C8 -> 5514 | D12: =D5-D8 -> 8448 | E12: =E5-E8 -> 4970 | F12: =F5-F8 -> 4242 | G12: =G5-G8 -> 3114 | H12: =H5-H8 -> 3004
A13: AVERAGE INVENTORY | B13: (Opening Inventory + Closing Inventory)/2 | C13: =(C6+D6)/2 -> 4218.5 | D13: =(D6+E6)/2 -> 4136.5 | E13: =(E6+F6)/2 -> 4173.5 | F13: =(F6+G6)/2 -> 3837.5 | G13: =(G6+H6)/2 -> 3173
A14: AVERAGE RECEIVABLES | B14: (Opening Receivables + Closing Receivables)/2 | C14: =(C7+D7)/2 -> 3408 | D14: =(D7+E7)/2 -> 3038 | E14: =(E7+F7)/2 -> 2657.5 | F14: =(F7+G7)/2 -> 1997 | G14: =(G7+H7)/2 -> 1453.5
A15: AVERAGE PAYABLES | B15: (Opening Payables + Closing Payables)/2 | C15: =(C9+D9)/2 -> 10900.5 | D15: =(D9+E9)/2 -> 10030 | E15: =(E9+F9)/2 -> 9321 | F15: =(F9+G9)/2 -> 8935 | G15: =(G9+H9)/2 -> 8168.5
A16: DAYS INVENTORY OUTSTANDING (DIO) (In Days) | B16: (Average Inventory / COGS)*365 | C16: =(C13/C4)*365 -> 50.354912 | D16: =(D13/D4)*365 -> 50.733283 | E16: =(E13/E4)*365 -> 48.030253 | F16: =(F13/F4)*365 -> 54.427336 | G16: =(G13/G4)*365 -> 52.291178
A17: DAYS SALES OUTSTANDING (DSO) (In Days) | B17: (Average Receivables / Revenue)*365 | C17: =(C14/C3)*365 -> 19.97046 | D17: =(D14/D3)*365 -> 18.188334 | E17: =(E14/E3)*365 -> 16.288897 | F17: =(F14/F3)*365 -> 14.140316 | G17: =(G14/G3)*365 -> 11.453283
A18: DAYS PAYABLE OUTSTANDING (DPO) (In Days) | B18: (Average Payables / COGS)*365 | C18: =(C15/C4)*365 -> 130.11585 | D18: =(D15/D4)*365 -> 123.01579 | E18: =(E15/E4)*365 -> 107.26967 | F18: =(F15/F4)*365 -> 126.72528 | G18: =(G15/G4)*365 -> 134.61723
A19: CASH CONVERSION CYCLE (CCC) (In Days) | B19: DIO + DSO - DPO | C19: =C16+C17-C18 -> -59.790479 | D19: =D16+D17-D18 -> -54.094176 | E19: =E16+E17-E18 -> -42.950525 | F19: =F16+F17-F18 -> -58.157625 | G19: =G16+G17-G18 -> -70.872774
A21: ITC LIMITED
A22: Figures (In Crores) | C22: FY25 | D22: FY24 | E22: FY23 | F22: FY22 | G22: FY21 | H22: FY20
A23: Net Revenue from Operations | C23: 69323.52 | D23: 65440.81 | E23: 66043.27 | F23: 56341.27 | G23: 45485.13 | H23: 45619
A24: COGS | C24: 31735.84 | D24: 26982.1 | E24: 28880.18 | F24: 26232.52 | G24: 19974 | H24: =13121+4289-176 -> 17234
A25: Current Assets | C25: 43893.28 | D25: 41065.54 | E25: 39670.89 | F25: 34232.45 | G25: 34991.99 | H25: 39505.35
A26: Inventory | C26: 15836.14 | D26: 14302.88 | E26: 11914.13 | F26: 10973.59 | G26: 10507.22 | H26: 8965
A27: Trade Receivables | C27: 4719.67 | D27: 4025.82 | E27: 2956.17 | F27: 2461.9 | G27: 2501.7 | H27: 2562
A28: Current Liability | C28: 14334.11 | D28: 13690.4 | E28: 13739.41 | F28: 12163.71 | G28: 10689.68 | H28: 9559.77
A29: Trade Payables | C29: 4807.3 | D29: 4797.83 | E29: 4658.99 | F29: 4417.26 | G29: 4318.73 | H29: 3629
A31: ANALYSIS PART
A32: WORKING CAPITAL | B32: CURRENT ASSETS - CURRENT LIABILITY | C32: =C25-C28 -> 29559.17 | D32: =D25-D28 -> 27375.14 | E32: =E25-E28 -> 25931.48 | F32: =F25-F28 -> 22068.74 | G32: =G25-G28 -> 24302.31 | H32: =H25-H28 -> 29945.58
A33: AVERAGE INVENTORY | B33: (Opening Inventory + Closing Inventory)/2 | C33: =(C26+D26)/2 -> 15069.51 | D33: =(D26+E26)/2 -> 13108.505 | E33: =(E26+F26)/2 -> 11443.86 | F33: =(F26+G26)/2 -> 10740.405 | G33: =(G26+H26)/2 -> 9736.11
A34: AVERAGE RECEIVABLES | B34: (Opening Receivables + Closing Receivables)/2 | C34: =(C27+D27)/2 -> 4372.745 | D34: =(D27+E27)/2 -> 3490.995 | E34: =(E27+F27)/2 -> 2709.035 | F34: =(F27+G27)/2 -> 2481.8 | G34: =(G27+H27)/2 -> 2531.85
A35: AVERAGE PAYABLES | B35: (Opening Payables + Closing Payables)/2 | C35: =(C29+D29)/2 -> 4802.565 | D35: =(D29+E29)/2 -> 4728.41 | E35: =(E29+F29)/2 -> 4538.125 | F35: =(F29+G29)/2 -> 4367.995 | G35: =(G29+H29)/2 -> 3973.865
A36: DAYS INVENTORY OUTSTANDING (DIO) (In Days) | B36: (Average Inventory / COGS)*365 | C36: =(C33/C24)*365 -> 173.31733 | D36: =(D33/D24)*365 -> 177.32513 | E36: =(E33/E24)*365 -> 144.63237 | F36: =(F33/F24)*365 -> 149.44229 | G36: =(G33/G24)*365 -> 177.9153
A37: DAYS SALES OUTSTANDING (DSO) (In Days) | B37: (Average Receivables / Revenue)*365 | C37: =(C34/C23)*365 -> 23.023238 | D37: =(D34/D23)*365 -> 19.471232 | E37: =(E34/E23)*365 -> 14.971969 | F37: =(F34/F23)*365 -> 16.078037 | G37: =(G34/G23)*365 -> 20.317085
A38: DAYS PAYABLE OUTSTANDING (DPO) (In Days) | B38: (Average Payables / COGS)*365 | C38: =(C35/C24)*365 -> 55.235224 | D38: =(D35/D24)*365 -> 63.963504 | E38: =(E35/E24)*365 -> 57.354754 | F38: =(F35/F24)*365 -> 60.776402 | G38: =(G35/G24)*365 -> 72.617439
A39: CASH CONVERSION CYCLE (CCC) (In Days) | B39: DIO + DSO - DPO | C39: =C36+C37-C38 -> 141.10535 | D39: =D36+D37-D38 -> 132.83286 | E39: =E36+E37-E38 -> 102.24959 | F39: =F36+F37-F38 -> 104.74392 | G39: =G36+G37-G38 -> 125.61494
A41: NESTLE INDIA LTD
A42: Figures (In Crores) | C42: FY25 | D42: FY24 | E42: FY23 | F42: FY22 | G42: FY21 | H42: FY20
A43: Net Revenue from Operations | C43: 20077.5 | D43: 24275.48 | E43: 19021.05 | F43: 16789.53 | G43: 14633.72 | H43: 13290.16
A44: COGS | C44: 8749.8 | D44: 10708.57 | E44: 8432.71 | F44: 7749.86 | G44: 6318.92 | H44: =5554.24+189-69 -> 5674.24
...

Sheet Automotive
A1: TATA MOTORS
A2: Figures (In Crores) | C2: FY25 | D2: FY24 | E2: FY23 | F2: FY22 | G2: FY21 | H2: FY20
A3: Net Revenue from Operations | C3: 439695 | D3: 437927.77 | E3: 345966.96 | F3: 278453.62 | G3: 249794.75 | H3: 261067.97
A4: COGS | C4: 282418 | D4: 283762.32 | E4: 237145.35 | F4: 190109.77 | G4: 163518.15 | H4: =152671+12228+4188+2232 -> 171319
A5: Current Assets | C5: 160325 | D5: 168392.15 | E5: 151528.47 | F5: 146977.54 | G5: 146887.64 | H5: 119587.25
A6: Inventory | C6: 47269 | D6: 47788.29 | E6: 40755.39 | F6: 35240.34 | G6: 36088.59 | H6: 37456.88
A7: Trade Receivables | C7: 13248 | D7: 16951.81 | E7: 15737.97 | F7: 12442.12 | G7: 12679.08 | H7: 11172.69
A8: Current Liability | C8: 166684 | D8: 173617 | E8: 155027.33 | F8: 150682.81 | G8: 157749.18 | H8: 140454.05
A9: Trade Payables | C9: 97368 | D9: 88042.95 | E9: 72055.77 | F9: 59970.38 | G9: 68179.8 | H9: 63626.88
A11: ANALYSIS PART
A12: WORKING CAPITAL | B12: CURRENT ASSETS - CURRENT LIABILITY | C12: =C5-C8 -> -6359 | D12: =D5-D8 -> -5224.85 | E12: =E5-E8 -> -3498.86 | F12: =F5-F8 -> -3705.27 | G12: =G5-G8 -> -10861.54 | H12: =H5-H8 -> -20866.8
A13: AVERAGE INVENTORY | B13: (Opening Inventory + Closing Inventory)/2 | C13: =(C6+D6)/2 -> 47528.645 | D13: =(D6+E6)/2 -> 44271.84 | E13: =(E6+F6)/2 -> 37997.865 | F13: =(F6+G6)/2 -> 35664.465 | G13: =(G6+H6)/2 -> 36772.735
A14: AVERAGE RECEIVABLES | B14: (Opening Receivables + Closing Receivables)/2 | C14: =(C7+D7)/2 -> 15099.905 | D14: =(D7+E7)/2 -> 16344.89 | E14: =(E7+F7)/2 -> 14090.045 | F14: =(F7+G7)/2 -> 12560.6 | G14: =(G7+H7)/2 -> 11925.885
A15: AVERAGE PAYABLES | B15: (Opening Payables + Closing Payables)/2 | C15: =(C9+D9)/2 -> 92705.475 | D15: =(D9+E9)/2 -> 80049.36 | E15: =(E9+F9)/2 -> 66013.075 | F15: =(F9+G9)/2 -> 64075.09 | G15: =(G9+H9)/2 -> 65903.34
A16: DAYS INVENTORY OUTSTANDING (DIO) (In Days) | B16: (Average Inventory / COGS)*365 | C16: =(C13/C4)*365 -> 61.426522 | D16: =(D13/D4)*365 -> 56.946326 | E16: =(E13/E4)*365 -> 58.484051 | F16: =(F13/F4)*365 -> 68.473755 | G16: =(G13/G4)*365 -> 82.082926
A17: DAYS SALES OUTSTANDING (DSO) (In Days) | B17: (Average Receivables / Revenue)*365 | C17: =(C14/C3)*365 -> 12.534746 | D17: =(D14/D3)*365 -> 13.622988 | E17: =(E14/E3)*365 -> 14.865195 | F17: =(F14/F3)*365 -> 16.46457 | G17: =(G14/G3)*365 -> 17.426099
A18: DAYS PAYABLE OUTSTANDING (DPO) (In Days) | B18: (Average Payables / COGS)*365 | C18: =(C15/C4)*365 -> 119.81353 | D18: =(D15/D4)*365 -> 102.96651 | E18: =(E15/E4)*365 -> 101.60339 | F18: =(F15/F4)*365 -> 123.02055 | G18: =(G15/G4)*365 -> 147.10733
A19: CASH CONVERSION CYCLE (CCC) (In Days) | B19: DIO + DSO - DPO | C19: =C16+C17-C18 -> -45.852265 | D19: =D16+D17-D18 -> -32.397198 | E19: =E16+E17-E18 -> -28.254148 | F19: =F16+F17-F18 -> -38.082223 | G19: =G16+G17-G18 -> -47.598309
A21: MAHINDRA AND MAHINDRA
A22: Figures (In Crores) | C22: FY25 | D22: FY24 | E22: FY23 | F22: FY22 | G22: FY21 | H22: FY20
A23: Net Revenue from Operations | C23: 158749.75 | D23: 138279.3 | E23: 121268.55 | F23: 90170.57 | G23: 74277.78 | H23: 75381.93
A24: COGS | C24: 95742.72 | D24: 83624.75 | E24: 73987.56 | F24: 51803.19 | G24: 38406.79 | H24: 38421.9
A25: Current Assets | C25: 126573.27 | D25: 98265.64 | E25: 91325.44 | F25: 75148 | G25: 72137.91 | H25: 64045.43
A26: Inventory | C26: 20330.93 | D26: 18590.47 | E26: 16854.97 | F26: 11595.82 | G26: 9615.41 | H26: 11111.86
A27: Trade Receivables | C27: 8279.7 | D27: 7459.4 | E27: 7028.02 | F27: 6373.95 | G27: 6007.76 | H27: 6928.28
A28: Current Liability | C28: 90322.01 | D28: 75545.65 | E28: 70579.41 | F28: 56288.33 | G28: 51446.01 | H28: 54009.52
A29: Trade Payables | C29: 30855.3 | D29: 25665.64 | E29: 23835.66 | F29: 19036.55 | G29: 15505.79 | H29: 14985.35
A31: ANALYSIS PART
A32: WORKING CAPITAL | B32: CURRENT ASSETS - CURRENT LIABILITY | C32: =C25-C28 -> 36251.26 | D32: =D25-D28 -> 22719.99 | E32: =E25-E28 -> 20746.03 | F32: =F25-F28 -> 18859.67 | G32: =G25-G28 -> 20691.9 | H32: =H25-H28 -> 10035.91
A33: AVERAGE INVENTORY | B33: (Opening Inventory + Closing Inventory)/2 | C33: =(C26+D26)/2 -> 19460.7 | D33: =(D26+E26)/2 -> 17722.72 | E33: =(E26+F26)/2 -> 14225.395 | F33: =(F26+G26)/2 -> 10605.615 | G33: =(G26+H26)/2 -> 10363.635
A34: AVERAGE RECEIVABLES | B34: (Opening Receivables + Closing Receivables)/2 | C34: =(C27+D27)/2 -> 7869.55 | D34: =(D27+E27)/2 -> 7243.71 | E34: =(E27+F27)/2 -> 6700.985 | F34: =(F27+G27)/2 -> 6190.855 | G34: =(G27+H27)/2 -> 6468.02
A35: AVERAGE PAYABLES | B35: (Opening Payables + Closing Payables)/2 | C35: =(C29+D29)/2 -> 28260.47 | D35: =(D29+E29)/2 -> 24750.65 | E35: =(E29+F29)/2 -> 21436.105 | F35: =(F29+G29)/2 -> 17271.17 | G35: =(G29+H29)/2 -> 15245.57
A36: DAYS INVENTORY OUTSTANDING (DIO) (In Days) | B36: (Average Inventory / COGS)*365 | C36: =(C33/C24)*365 -> 74.190032 | D36: =(D33/D24)*365 -> 77.355003 | E36: =(E33/E24)*365 -> 70.177597 | F36: =(F33/F24)*365 -> 74.726083 | G36: =(G33/G24)*365 -> 98.491094
A37: DAYS SALES OUTSTANDING (DSO) (In Days) | B37: (Average Receivables / Revenue)*365 | C37: =(C34/C23)*365 -> 18.093797 | D37: =(D34/D23)*365 -> 19.12039 | E37: =(E34/E23)*365 -> 20.168952 | F37: =(F34/F23)*365 -> 25.059862 | G37: =(G34/G23)*365 -> 31.783762
A38: DAYS PAYABLE OUTSTANDING (DPO) (In Days) | B38: (Average Payables / COGS)*365 | C38: =(C35/C24)*365 -> 107.7374 | D38: =(D35/D24)*365 -> 108.03007 | E38: =(E35/E24)*365 -> 105.74992 | F38: =(F35/F24)*365 -> 121.6909 | G38: =(G35/G24)*365 -> 144.8867
A39: CASH CONVERSION CYCLE (CCC) (In Days) | B39: DIO + DSO - DPO | C39: =C36+C37-C38 -> -15.453569 | D39: =D36+D37-D38 -> -11.554673 | E39: =E36+E37-E38 -> -15.403368 | F39: =F36+F37-F38 -> -21.904959 | G39: =G36+G37-G38 -> -14.611843
A41: MARUTI SUZUKI INDIA
A42: Figures (In Crores) | C42: FY25 | D42: FY24 | E42: FY23 | F42: FY22 | G42: FY21 | H42: FY20
A43: Net Revenue from Operations | C43: 152913 | D43: 141858.2 | E43: 117571.3 | F43: 88329.8 | G43: 70372 | H43: 75660
A44: COGS | C44: 107490.8 | D44: 99740.9 | E44: 86250.8 | F44: 66044 | G44: 50824.1 | H44: =34634+18767.2-238.7 -> 53162.5
...

Sheet Energy 
A1: RELIANCE INDUSTRIES (sa)
A2: Figures (In Crores) | C2: FY25 | D2: FY24 | E2: FY23 | F2: FY22 | G2: FY21 | H2: FY20
A3: Net Revenue from Operations | C3: 517349 | D3: 534534 | E3: 528315 | F3: 423703 | G3: 245667 | H3: 336953
A4: COGS | C4: 432209 | D4: 432598 | E4: 439391 | F4: 350736 | G4: 194548 | H4: 266135
A5: Current Assets | C5: 269563 | D5: 262625 | E5: 265932 | F5: 222398 | G5: 210719 | H5: 166654
A6: Inventory | C6: 89216 | D6: 85100 | E6: 48926 | F6: 45923 | G6: 37437 | H6: 38802
A7: Trade Receivables | C7: 15591 | D7: 14740 | E7: 16898 | F7: 14394 | G7: 4159 | H7: 7483
A8: Current Liability | C8: 257935 | D8: 240014 | E8: 237276 | F8: 200982 | G8: 201787 | H8: 330682
A9: Trade Payables | C9: 122379 | D9: 129859 | E9: 110722 | F9: 134005 | G9: 86999 | H9: 71048
A11: ANALYSIS PART
A12: WORKING CAPITAL | B12: CURRENT ASSETS - CURRENT LIABILITY | C12: =C5-C8 -> 11628 | D12: =D5-D8 -> 22611 | E12: =E5-E8 -> 28656 | F12: =F5-F8 -> 21416 | G12: =G5-G8 -> 8932 | H12: =H5-H8 -> -164028
A13: AVERAGE INVENTORY | B13: (Opening Inventory + Closing Inventory)/2 | C13: =(C6+D6)/2 -> 87158 | D13: =(D6+E6)/2 -> 67013 | E13: =(E6+F6)/2 -> 47424.5 | F13: =(F6+G6)/2 -> 41680 | G13: =(G6+H6)/2 -> 38119.5
A14: AVERAGE RECEIVABLES | B14: (Opening Receivables + Closing Receivables)/2 | C14: =(C7+D7)/2 -> 15165.5 | D14: =(D7+E7)/2 -> 15819 | E14: =(E7+F7)/2 -> 15646 | F14: =(F7+G7)/2 -> 9276.5 | G14: =(G7+H7)/2 -> 5821
A15: AVERAGE PAYABLES | B15: (Opening Payables + Closing Payables)/2 | C15: =(C9+D9)/2 -> 126119 | D15: =(D9+E9)/2 -> 120290.5 | E15: =(E9+F9)/2 -> 122363.5 | F15: =(F9+G9)/2 -> 110502 | G15: =(G9+H9)/2 -> 79023.5
A16: DAYS INVENTORY OUTSTANDING (DIO) (In Days) | B16: (Average Inventory / COGS)*365 | C16: =(C13/C4)*365 -> 73.60483 | D16: =(D13/D4)*365 -> 56.541512 | E16: =(E13/E4)*365 -> 39.395305 | F16: =(F13/F4)*365 -> 43.375074 | G16: =(G13/G4)*365 -> 71.517659
A17: DAYS SALES OUTSTANDING (DSO) (In Days) | B17: (Average Receivables / Revenue)*365 | C17: =(C14/C3)*365 -> 10.699562 | D17: =(D14/D3)*365 -> 10.801811 | E17: =(E14/E3)*365 -> 10.809441 | F17: =(F14/F3)*365 -> 7.9912639 | G17: =(G14/G3)*365 -> 8.6485568
A18: DAYS PAYABLE OUTSTANDING (DPO) (In Days) | B18: (Average Payables / COGS)*365 | C18: =(C15/C4)*365 -> 106.50735 | D18: =(D15/D4)*365 -> 101.49384 | E18: =(E15/E4)*365 -> 101.64677 | F18: =(F15/F4)*365 -> 114.99598 | G18: =(G15/G4)*365 -> 148.25944
A19: CASH CONVERSION CYCLE (CCC) (In Days) | B19: DIO + DSO - DPO | C19: =C16+C17-C18 -> -22.202958 | D19: =D16+D17-D18 -> -34.150518 | E19: =E16+E17-E18 -> -51.442027 | F19: =F16+F17-F18 -> -63.629642 | G19: =G16+G17-G18 -> -68.093224
A21: INDIAN OIL CORPORATION
A22: Figures (In Crores) | C22: FY25 | D22: FY24 | E22: FY23 | F22: FY22 | G22: FY21 | H22: FY20
A23: Net Revenue from Operations | C23: 758105.81 | D23: 776351.85 | E23: 841755.91 | F23: 589335.74 | G23: 363949.67 | H23: 483763.04
A24: COGS | C24: 656785.5 | D24: 638799.16 | E24: 747634.99 | F24: 486952.9 | G24: 275466.59 | H24: =281080+139463+5-5414.35 -> 415133.65
A25: Current Assets | C25: 157643.15 | D25: 158448.27 | E25: 158865.49 | F25: 146860.69 | G25: 116208.69 | H25: 110735.28
A26: Inventory | C26: 113878.49 | D26: 121375.83 | E26: 121107.58 | F26: 111736.51 | G26: 83427.46 | H26: 67010.76
A27: Trade Receivables | C27: 18550.96 | D27: 13831.45 | E27: 16271.21 | F27: 18700.42 | G27: 13800.2 | H27: 13259.48
A28: Current Liability | C28: 230614.41 | D28: 216403.93 | E28: 206658.33 | F28: 192154.7 | G28: 162174.89 | H28: 161517.84
A29: Trade Payables | C29: 60534.94 | D29: 59454.1 | E29: 54734.1 | F29: 49045.91 | G29: 37247.97 | H29: 27576.26
A31: ANALYSIS PART
A32: WORKING CAPITAL | B32: CURRENT ASSETS - CURRENT LIABILITY | C32: =C25-C28 -> -72971.26 | D32: =D25-D28 -> -57955.66 | E32: =E25-E28 -> -47792.84 | F32: =F25-F28 -> -45294.01 | G32: =G25-G28 -> -45966.2 | H32: =H25-H28 -> -50782.56
A33: AVERAGE INVENTORY | B33: (Opening Inventory + Closing Inventory)/2 | C33: =(C26+D26)/2 -> 117627.16 | D33: =(D26+E26)/2 -> 121241.71 | E33: =(E26+F26)/2 -> 116422.04 | F33: =(F26+G26)/2 -> 97581.985 | G33: =(G26+H26)/2 -> 75219.11
A34: AVERAGE RECEIVABLES | B34: (Opening Receivables + Closing Receivables)/2 | C34: =(C27+D27)/2 -> 16191.205 | D34: =(D27+E27)/2 -> 15051.33 | E34: =(E27+F27)/2 -> 17485.815 | F34: =(F27+G27)/2 -> 16250.31 | G34: =(G27+H27)/2 -> 13529.84
A35: AVERAGE PAYABLES | B35: (Opening Payables + Closing Payables)/2 | C35: =(C29+D29)/2 -> 59994.52 | D35: =(D29+E29)/2 -> 57094.1 | E35: =(E29+F29)/2 -> 51890.005 | F35: =(F29+G29)/2 -> 43146.94 | G35: =(G29+H29)/2 -> 32412.115
A36: DAYS INVENTORY OUTSTANDING (DIO) (In Days) | B36: (Average Inventory / COGS)*365 | C36: =(C33/C24)*365 -> 65.369764 | D36: =(D33/D24)*365 -> 69.275643 | E36: =(E33/E24)*365 -> 56.837958 | F36: =(F33/F24)*365 -> 73.143469 | G36: =(G33/G24)*365 -> 99.667169
A37: DAYS SALES OUTSTANDING (DSO) (In Days) | B37: (Average Receivables / Revenue)*365 | C37: =(C34/C23)*365 -> 7.7954683 | D37: =(D34/D23)*365 -> 7.0763475 | E37: =(E34/E23)*365 -> 7.5821534 | F37: =(F34/F23)*365 -> 10.064489 | G37: =(G34/G23)*365 -> 13.568886
A38: DAYS PAYABLE OUTSTANDING (DPO) (In Days) | B38: (Average Payables / COGS)*365 | C38: =(C35/C24)*365 -> 33.341174 | D38: =(D35/D24)*365 -> 32.622689 | E38: =(E35/E24)*365 -> 25.33302 | F38: =(F35/F24)*365 -> 32.341184 | G38: =(G35/G24)*365 -> 42.946849
A39: CASH CONVERSION CYCLE (CCC) (In Days) | B39: DIO + DSO - DPO | C39: =C36+C37-C38 -> 39.824058 | D39: =D36+D37-D38 -> 43.729301 | E39: =E36+E37-E38 -> 39.087092 | F39: =F36+F37-F38 -> 50.866775 | G39: =G36+G37-G38 -> 70.289206
A41: Bharat Petroleum Corporation
A42: Figures (In Crores) | C42: FY25 | D42: FY24 | E42: FY23 | F42: FY22 | G42: FY21 | H42: FY20
A43: Net Revenue from Operations | C43: 440271.86 | D43: 448083.03 | E43: 473187.18 | F43: 346791.12 | G43: 230162.63 | H43: 284571.9
A44: COGS | C44: 385296.91 | D44: 376096.15 | E44: 433212.29 | F44: 303401.27 | G44: 187398.76 | H44: 252592.13
...

Sheet Metals
A1: HINDALCO INDUSTRIES
A2: Figures (In Crores) | C2: FY25 | D2: FY24 | E2: FY23 | F2: FY22 | G2: FY21 | H2: FY20
A3: Net Revenue from Operations | C3: 238496 | D3: 215962 | E3: 223202 | F3: 195059 | G3: 131985 | H3: 118144
A4: COGS | C4: 159345 | D4: 148331 | E4: 158116 | F4: 128686 | G4: 85228 | H4: =77727+256-17 -> 77966
A5: Current Assets | C5: 101959 | D5: 82343 | E5: 89311 | F5: 98543 | G5: 67628 | H5: 66282
A6: Inventory | C6: 48801 | D6: 40812 | E6: 42958 | F6: 44483 | G6: 30668 | H6: 22384
A7: Trade Receivables | C7: 19834 | D7: 16404 | E7: 16214 | F7: 21076 | G7: 12959 | H7: 9345
A8: Current Liability | C8: 65516 | D8: 59351 | E8: 60457 | F8: 77273 | G8: 48493 | H8: 37217
A9: Trade Payables | C9: 40632 | D9: 34444 | E9: 35860 | F9: 41382 | G9: 28280 | H9: 18300
A11: ANALYSIS PART
A12: WORKING CAPITAL | B12: CURRENT ASSETS - CURRENT LIABILITY | C12: =C5-C8 -> 36443 | D12: =D5-D8 -> 22992 | E12: =E5-E8 -> 28854 | F12: =F5-F8 -> 21270 | G12: =G5-G8 -> 19135 | H12: =H5-H8 -> 29065
A13: AVERAGE INVENTORY | B13: (Opening Inventory + Closing Inventory)/2 | C13: =(C6+D6)/2 -> 44806.5 | D13: =(D6+E6)/2 -> 41885 | E13: =(E6+F6)/2 -> 43720.5 | F13: =(F6+G6)/2 -> 37575.5 | G13: =(G6+H6)/2 -> 26526
A14: AVERAGE RECEIVABLES | B14: (Opening Receivables + Closing Receivables)/2 | C14: =(C7+D7)/2 -> 18119 | D14: =(D7+E7)/2 -> 16309 | E14: =(E7+F7)/2 -> 18645 | F14: =(F7+G7)/2 -> 17017.5 | G14: =(G7+H7)/2 -> 11152
A15: AVERAGE PAYABLES | B15: (Opening Payables + Closing Payables)/2 | C15: =(C9+D9)/2 -> 37538 | D15: =(D9+E9)/2 -> 35152 | E15: =(E9+F9)/2 -> 38621 | F15: =(F9+G9)/2 -> 34831 | G15: =(G9+H9)/2 -> 23290
A16: DAYS INVENTORY OUTSTANDING (DIO) (In Days) | B16: (Average Inventory / COGS)*365 | C16: =(C13/C4)*365 -> 102.63499 | D16: =(D13/D4)*365 -> 103.06696 | E16: =(E13/E4)*365 -> 100.92579 | F16: =(F13/F4)*365 -> 106.5777 | G16: =(G13/G4)*365 -> 113.60105
A17: DAYS SALES OUTSTANDING (DSO) (In Days) | B17: (Average Receivables / Revenue)*365 | C17: =(C14/C3)*365 -> 27.729752 | D17: =(D14/D3)*365 -> 27.564039 | E17: =(E14/E3)*365 -> 30.489982 | F17: =(F14/F3)*365 -> 31.843634 | G17: =(G14/G3)*365 -> 30.840474
A18: DAYS PAYABLE OUTSTANDING (DPO) (In Days) | B18: (Average Payables / COGS)*365 | C18: =(C15/C4)*365 -> 85.985566 | D18: =(D15/D4)*365 -> 86.498979 | E18: =(E15/E4)*365 -> 89.153944 | F18: =(F15/F4)*365 -> 98.793303 | G18: =(G15/G4)*365 -> 99.742456
A19: CASH CONVERSION CYCLE (CCC) (In Days) | B19: DIO + DSO - DPO | C19: =C16+C17-C18 -> 44.379176 | D19: =D16+D17-D18 -> 44.132019 | E19: =E16+E17-E18 -> 42.26183 | F19: =F16+F17-F18 -> 39.628028 | G19: =G16+G17-G18 -> 44.699065
A21: TATA STEEL LTD
A22: Figures (In Crores) | C22: FY25 | D22: FY24 | E22: FY23 | F22: FY22 | G22: FY21 | H22: FY20
A23: Net Revenue from Operations | C23: 218542.51 | D23: 229170.78 | E23: 243352.69 | F23: 243959.17 | G23: 156477.4 | H23: 148971.71
A24: COGS | C24: 95000.65 | D24: 101915.74 | E24: 113238.3 | F24: 83478.74 | G24: 56617.58 | H24: 64587.08
A25: Current Assets | C25: 68391.54 | D25: 70548.24 | E25: 86665.54 | F25: 92556.61 | G25: 60211.9 | H25: 58732.72
A26: Inventory | C26: 44589.94 | D26: 49157.51 | E26: 54415.33 | F26: 48824.39 | G26: 33276.38 | H26: 31068.72
A27: Trade Receivables | C27: 5260.06 | D27: 6263.53 | E27: 8257.24 | F27: 12246.43 | G27: 9539.84 | H27: 7884.91
A28: Current Liability | C28: 86093.55 | D28: 98403.48 | E28: 97295.13 | F28: 90588 | G28: 70867.1 | H28: 61660.91
A29: Trade Payables | C29: 29314.38 | D29: 35434.66 | E29: 37832.54 | F29: 36764.87 | G29: 25967.49 | H29: 21380.85
A31: ANALYSIS PART
A32: WORKING CAPITAL | B32: CURRENT ASSETS - CURRENT LIABILITY | C32: =C25-C28 -> -17702.01 | D32: =D25-D28 -> -27855.24 | E32: =E25-E28 -> -10629.59 | F32: =F25-F28 -> 1968.61 | G32: =G25-G28 -> -10655.2 | H32: =H25-H28 -> -2928.19
A33: AVERAGE INVENTORY | B33: (Opening Inventory + Closing Inventory)/2 | C33: =(C26+D26)/2 -> 46873.725 | D33: =(D26+E26)/2 -> 51786.42 | E33: =(E26+F26)/2 -> 51619.86 | F33: =(F26+G26)/2 -> 41050.385 | G33: =(G26+H26)/2 -> 32172.55
A34: AVERAGE RECEIVABLES | B34: (Opening Receivables + Closing Receivables)/2 | C34: =(C27+D27)/2 -> 5761.795 | D34: =(D27+E27)/2 -> 7260.385 | E34: =(E27+F27)/2 -> 10251.835 | F34: =(F27+G27)/2 -> 10893.135 | G34: =(G27+H27)/2 -> 8712.375
A35: AVERAGE PAYABLES | B35: (Opening Payables + Closing Payables)/2 | C35: =(C29+D29)/2 -> 32374.52 | D35: =(D29+E29)/2 -> 36633.6 | E35: =(E29+F29)/2 -> 37298.705 | F35: =(F29+G29)/2 -> 31366.18 | G35: =(G29+H29)/2 -> 23674.17
A36: DAYS INVENTORY OUTSTANDING (DIO) (In Days) | B36: (Average Inventory / COGS)*365 | C36: =(C33/C24)*365 -> 180.09255 | D36: =(D33/D24)*365 -> 185.46736 | E36: =(E33/E24)*365 -> 166.38583 | F36: =(F33/F24)*365 -> 179.4875 | G36: =(G33/G24)*365 -> 207.40874
A37: DAYS SALES OUTSTANDING (DSO) (In Days) | B37: (Average Receivables / Revenue)*365 | C37: =(C34/C23)*365 -> 9.6230943 | D37: =(D34/D23)*365 -> 11.563606 | E37: =(E34/E23)*365 -> 15.376529 | F37: =(F34/F23)*365 -> 16.297786 | G37: =(G34/G23)*365 -> 20.322531
A38: DAYS PAYABLE OUTSTANDING (DPO) (In Days) | B38: (Average Payables / COGS)*365 | C38: =(C35/C24)*365 -> 124.38546 | D38: =(D35/D24)*365 -> 131.1992 | E38: =(E35/E24)*365 -> 120.22458 | F38: =(F35/F24)*365 -> 137.14457 | G38: =(G35/G24)*365 -> 152.62171
A39: CASH CONVERSION CYCLE (CCC) (In Days) | B39: DIO + DSO - DPO | C39: =C36+C37-C38 -> 65.330185 | D39: =D36+D37-D38 -> 65.831762 | E39: =E36+E37-E38 -> 61.53778 | F39: =F36+F37-F38 -> 58.64072 | G39: =G36+G37-G38 -> 75.109555
A41: JSW STEEL
A42: Figures (In Crores) | C42: FY25 | D42: FY24 | E42: FY23 | F42: FY22 | G42: FY21 | H42: FY20
A43: Net Revenue from Operations | C43: 168824 | D43: 175006 | E43: 165960 | F43: 146371 | G43: 79839 | H43: 73326
A44: COGS | C44: 99142 | D44: 101678 | E44: 93334 | F44: 59270 | G44: 32508 | H44: 38730
...

Sheet Pharma
A1: SUN PHARMACEUTICALS INDUSTRIES
A2: Figures (In Crores) | C2: FY25 | D2: FY24 | E2: FY23 | F2: FY22 | G2: FY21 | H2: FY20
A3: Net Revenue from Operations | C3: 52578.44 | D3: 48496.85 | E3: 43885.68 | F3: 38654.49 | G3: 33498.14 | H3: 32325.17
A4: COGS | C4: 10747.36 | D4: 11292.87 | E4: 11223.48 | F4: 10909.35 | G4: 8690.08 | H4: 9230.45
A5: Current Assets | C5: 52624.47 | D5: 43474.98 | E5: 39883.34 | F5: 35014.98 | G5: 30442.08 | H5: 31654.16
A6: Inventory | C6: 10243.33 | D6: 9868.29 | E6: 10513.05 | F6: 8996.81 | G6: 8997.02 | H6: 7874.99
A7: Trade Receivables | C7: 13046.11 | D7: 11249.37 | E7: 11438.51 | F7: 10592.89 | G7: 9061.4 | H7: 9421.24
A8: Current Liability | C8: 18194.21 | D8: 16984.4 | E8: 19907 | F8: 17200.55 | G8: 16145.63 | H8: 15706.43
A9: Trade Payables | C9: 6184.34 | D9: 5653.3 | E9: 5681.52 | F9: 4479.34 | G9: 3973.66 | H9: 3583.64
A11: ANALYSIS PART
A12: WORKING CAPITAL | B12: CURRENT ASSETS - CURRENT LIABILITY | C12: =C5-C8 -> 34430.26 | D12: =D5-D8 -> 26490.58 | E12: =E5-E8 -> 19976.34 | F12: =F5-F8 -> 17814.43 | G12: =G5-G8 -> 14296.45 | H12: =H5-H8 -> 15947.73
A13: AVERAGE INVENTORY | B13: (Opening Inventory + Closing Inventory)/2 | C13: =(C6+D6)/2 -> 10055.81 | D13: =(D6+E6)/2 -> 10190.67 | E13: =(E6+F6)/2 -> 9754.93 | F13: =(F6+G6)/2 -> 8996.915 | G13: =(G6+H6)/2 -> 8436.005
A14: AVERAGE RECEIVABLES | B14: (Opening Receivables + Closing Receivables)/2 | C14: =(C7+D7)/2 -> 12147.74 | D14: =(D7+E7)/2 -> 11343.94 | E14: =(E7+F7)/2 -> 11015.7 | F14: =(F7+G7)/2 -> 9827.145 | G14: =(G7+H7)/2 -> 9241.32
A15: AVERAGE PAYABLES | B15: (Opening Payables + Closing Payables)/2 | C15: =(C9+D9)/2 -> 5918.82 | D15: =(D9+E9)/2 -> 5667.41 | E15: =(E9+F9)/2 -> 5080.43 | F15: =(F9+G9)/2 -> 4226.5 | G15: =(G9+H9)/2 -> 3778.65
A16: DAYS INVENTORY OUTSTANDING (DIO) (In Days) | B16: (Average Inventory / COGS)*365 | C16: =(C13/C4)*365 -> 341.5137 | D16: =(D13/D4)*365 -> 329.37549 | E16: =(E13/E4)*365 -> 317.24113 | F16: =(F13/F4)*365 -> 301.01463 | G16: =(G13/G4)*365 -> 354.32836
A17: DAYS SALES OUTSTANDING (DSO) (In Days) | B17: (Average Receivables / Revenue)*365 | C17: =(C14/C3)*365 -> 84.32972 | D17: =(D14/D3)*365 -> 85.377465 | E17: =(E14/E3)*365 -> 91.61828 | F17: =(F14/F3)*365 -> 92.794082 | G17: =(G14/G3)*365 -> 100.6946
A18: DAYS PAYABLE OUTSTANDING (DPO) (In Days) | B18: (Average Payables / COGS)*365 | C18: =(C15/C4)*365 -> 201.01395 | D18: =(D15/D4)*365 -> 183.17794 | E18: =(E15/E4)*365 -> 165.22121 | F18: =(F15/F4)*365 -> 141.40829 | G18: =(G15/G4)*365 -> 158.71054
A19: CASH CONVERSION CYCLE (CCC) (In Days) | B19: DIO + DSO - DPO | C19: =C16+C17-C18 -> 224.82947 | D19: =D16+D17-D18 -> 231.57501 | E19: =E16+E17-E18 -> 243.6382 | F19: =F16+F17-F18 -> 252.40043 | G19: =G16+G17-G18 -> 296.31243
A21: DR REDDY'S LABORATORIES
A22: Figures (In Crores) | C22: FY25 | D22: FY24 | E22: FY23 | F22: FY22 | G22: FY21 | H22: FY20
A23: Net Revenue from Operations | C23: 32643.9 | D23: 28011.1 | E23: 24669.7 | F23: 21545.2 | G23: 19047.5 | H23: 17517
A24: COGS | C24: 9979.9 | D24: 8208.7 | E24: 7657.7 | F24: 7442.2 | G24: 6078.9 | H24: 5554.4
A25: Current Assets | C25: 25018.1 | D25: 24805.3 | E25: 20425.5 | F25: 17782.3 | G25: 14550.3 | H25: 12599.1
A26: Inventory | C26: 7108.5 | D26: 6355.2 | E26: 4867 | F26: 5088.4 | G26: 4541.2 | H26: 3506.7
A27: Trade Receivables | C27: 9042 | D27: 8029.8 | E27: 7248.5 | F27: 6676.4 | G27: 4964.1 | H27: 5027.8
A28: Current Liability | C28: 13033.8 | D28: 9588 | E28: 8572.1 | F28: 9765.8 | G28: 8103.8 | H28: 7214.1
A29: Trade Payables | C29: 2647.8 | D29: 2614.4 | E29: 2268.4 | F29: 2266.2 | G29: 1810.9 | H29: 1524.8
A31: ANALYSIS PART
A32: WORKING CAPITAL | B32: CURRENT ASSETS - CURRENT LIABILITY | C32: =C25-C28 -> 11984.3 | D32: =D25-D28 -> 15217.3 | E32: =E25-E28 -> 11853.4 | F32: =F25-F28 -> 8016.5 | G32: =G25-G28 -> 6446.5 | H32: =H25-H28 -> 5385
A33: AVERAGE INVENTORY | B33: (Opening Inventory + Closing Inventory)/2 | C33: =(C26+D26)/2 -> 6731.85 | D33: =(D26+E26)/2 -> 5611.1 | E33: =(E26+F26)/2 -> 4977.7 | F33: =(F26+G26)/2 -> 4814.8 | G33: =(G26+H26)/2 -> 4023.95
A34: AVERAGE RECEIVABLES | B34: (Opening Receivables + Closing Receivables)/2 | C34: =(C27+D27)/2 -> 8535.9 | D34: =(D27+E27)/2 -> 7639.15 | E34: =(E27+F27)/2 -> 6962.45 | F34: =(F27+G27)/2 -> 5820.25 | G34: =(G27+H27)/2 -> 4995.95
A35: AVERAGE PAYABLES | B35: (Opening Payables + Closing Payables)/2 | C35: =(C29+D29)/2 -> 2631.1 | D35: =(D29+E29)/2 -> 2441.4 | E35: =(E29+F29)/2 -> 2267.3 | F35: =(F29+G29)/2 -> 2038.55 | G35: =(G29+H29)/2 -> 1667.85
A36: DAYS INVENTORY OUTSTANDING (DIO) (In Days) | B36: (Average Inventory / COGS)*365 | C36: =(C33/C24)*365 -> 246.2074 | D36: =(D33/D24)*365 -> 249.49767 | E36: =(E33/E24)*365 -> 237.25929 | F36: =(F33/F24)*365 -> 236.14012 | G36: =(G33/G24)*365 -> 241.61308
A37: DAYS SALES OUTSTANDING (DSO) (In Days) | B37: (Average Receivables / Revenue)*365 | C37: =(C34/C23)*365 -> 95.442135 | D37: =(D34/D23)*365 -> 99.542315 | E37: =(E34/E23)*365 -> 103.01277 | F37: =(F34/F23)*365 -> 98.601603 | G37: =(G34/G23)*365 -> 95.73549
A38: DAYS PAYABLE OUTSTANDING (DPO) (In Days) | B38: (Average Payables / COGS)*365 | C38: =(C35/C24)*365 -> 96.228569 | D38: =(D35/D24)*365 -> 108.5569 | E38: =(E35/E24)*365 -> 108.06959 | F38: =(F35/F24)*365 -> 99.979945 | G38: =(G35/G24)*365 -> 100.14398
A39: CASH CONVERSION CYCLE (CCC) (In Days) | B39: DIO + DSO - DPO | C39: =C36+C37-C38 -> 245.42097 | D39: =D36+D37-D38 -> 240.48309 | E39: =E36+E37-E38 -> 232.20248 | F39: =F36+F37-F38 -> 234.76178 | G39: =G36+G37-G38 -> 237.20459
A41: AUROBINDO PHARMA
A42: Figures (In Crores) | C42: FY25 | D42: FY24 | E42: FY23 | F42: FY22 | G42: FY21 | H42: FY20
A43: Net Revenue from Operations | C43: 31723.73 | D43: 29001.87 | E43: 24855.38 | F43: 23455.49 | G43: 24774.62 | H43: 23098.51
A44: COGS | C44: 13026.24 | D44: 12602.9 | E44: 11293.26 | F44: 10140.28 | G44: 9902.47 | H44: 9735.23
...
